<?xml version='1.0'?>
<sdf version='1.4'>

	<model name="Line_follower">
		<static>false</static>
		<link name='chassis'>
			<pose>0 0 .3 0 0 0</pose>
			<collision name='collision'>
				<geometry><box><size>.8 .5 .1</size></box></geometry>
			</collision>

			<visual name='visual'>
				<geometry><box><size>.8 .5 .1</size></box></geometry>
			</visual>
		</link>

		<link name="left_back">
			<pose>-0.4 0.4 0.3 0 1.5707 1.5707</pose>
			<collision name="collision">
				<geometry>
					<cylinder>
					<radius>.3</radius>
					<length>.05</length>
					</cylinder>
				</geometry>
			</collision>
			<visual name="visual">
				<geometry>
					<cylinder>
					<radius>.3</radius>
					<length>.05</length>
					</cylinder>
				</geometry>
			</visual>
		</link>

		<link name="left_front">
			<pose>0.4 0.4 0.3 0 1.5707 1.5707</pose>
			<collision name="collision">
				<geometry>
					<cylinder>
					<radius>.3</radius>
					<length>.05</length>
					</cylinder>
				</geometry>
			</collision>
			<visual name="visual">
				<geometry>
					<cylinder>
					<radius>.3</radius>
					<length>.05</length>
					</cylinder>
				</geometry>
			</visual>
		</link>

		<link name="right_back">
			<pose>-0.4 -0.4 0.3 0 1.5707 1.5707</pose>
			<collision name="collision">
				<geometry>
					<cylinder>
					<radius>.3</radius>
					<length>.05</length>
					</cylinder>
				</geometry>
			</collision>
			<visual name="visual">
				<geometry>
					<cylinder>
					<radius>.3</radius>
					<length>.05</length>
					</cylinder>
				</geometry>
			</visual>
		</link>

		<link name="right_front">
			<pose>0.4 -0.4 0.3 0 1.5707 1.5707</pose>
			<collision name="collision">
				<geometry>
					<cylinder>
					<radius>.3</radius>
					<length>.05</length>
					</cylinder>
				</geometry>
			</collision>
			<visual name="visual">
				<geometry>
					<cylinder>
					<radius>.3</radius>
					<length>.05</length>
					</cylinder>
				</geometry>
			</visual>
		</link>

		<joint type="revolute" name="left_front_hinge">
			<pose>0 0 -0.09 0 0 0</pose>
			<child>left_front</child>
			<parent>chassis</parent>
			<axis>
				<xyz>0 1 0</xyz>
			</axis>
		</joint>

		<joint type="revolute" name="right_back_hinge">
			<pose>0 0 0.09 0 0 0</pose>
			<child>right_back</child>
			<parent>chassis</parent>
			<axis>
				<xyz>0 1 0</xyz>
			</axis>
		</joint>

		<joint type="revolute" name="right_front_hinge">
			<pose>0 0 0.09 0 0 0</pose>
			<child>right_front</child>
			<parent>chassis</parent>
			<axis>
				<xyz>0 1 0</xyz>
			</axis>
		</joint>

		<joint type="revolute" name="left_back_hinge">
			<pose>0 0 -0.09 0 0 0</pose>
			<child>left_back</child>
			<parent>chassis</parent>
			<axis>
				<xyz>0 1 0</xyz>
			</axis>
		</joint>
	
		<link name='camera::link'>
			<sensor name='camera' type='camera'>
				<camera>
					<horizontal_fov>1.047</horizontal_fov>
					<image>
						<width>320</width>
						<height>240</height>
					</image>
					<clip>
						<near>0.01</near>
						<far>100</far>
					</clip>
					</camera>
				<always_on>1</always_on>
				<update_rate>6</update_rate>
				<visualize>1</visualize>
				
			</sensor>
			<pose>0.35 -0 0.2 0 1.5707 0</pose>
			<visual name='visual'>
				<geometry>
				<box>
					<size>0.1 0.1 0.1</size>
				</box>
				</geometry>
			</visual>
			<collision name='collision'>
				<geometry>
				<box>
					<size>0.1 0.1 0.1</size>
				</box>
				</geometry>
			</collision>
		</link>
	
		<joint name='camera_joint' type='fixed'>
			<parent>chassis</parent>
			<child>camera::link</child>
			<pose>0 0 0 0 -0 0</pose>
		</joint>
		<plugin name="controller" filename="libcontroller.so">
			<velocity>0.3</velocity>
			<positive>81.3</positive>
			<negative>85</negative>
			<ratio>5</ratio>
		</plugin>
	</model>
</sdf>
